{"data": "Traceback (most recent call last):\n  File \"/Users/mhrezaei/Documents/Research/negation/negation-and-nlu/env/lib/python3.11/site-packages/huggingface_hub/utils/_errors.py\", line 261, in hf_raise_for_status\n    response.raise_for_status()\n  File \"/Users/mhrezaei/Documents/Research/negation/negation-and-nlu/env/lib/python3.11/site-packages/requests/models.py\", line 1021, in raise_for_status\n    raise HTTPError(http_error_msg, response=self)\nrequests.exceptions.HTTPError: 404 Client Error: Not Found for url: https://huggingface.co/model/resolve/main/config.json\n\nThe above exception was the direct cause of the following exception:\n\nTraceback (most recent call last):\n  File \"/Users/mhrezaei/Documents/Research/negation/negation-and-nlu/env/lib/python3.11/site-packages/transformers/utils/hub.py\", line 430, in cached_file\n    resolved_file = hf_hub_download(\n                    ^^^^^^^^^^^^^^^^\n  File \"/Users/mhrezaei/Documents/Research/negation/negation-and-nlu/env/lib/python3.11/site-packages/huggingface_hub/utils/_validators.py\", line 118, in _inner_fn\n    return fn(*args, **kwargs)\n           ^^^^^^^^^^^^^^^^^^^\n  File \"/Users/mhrezaei/Documents/Research/negation/negation-and-nlu/env/lib/python3.11/site-packages/huggingface_hub/file_download.py\", line 1346, in hf_hub_download\n    raise head_call_error\n  File \"/Users/mhrezaei/Documents/Research/negation/negation-and-nlu/env/lib/python3.11/site-packages/huggingface_hub/file_download.py\", line 1232, in hf_hub_download\n    metadata = get_hf_file_metadata(\n               ^^^^^^^^^^^^^^^^^^^^^\n  File \"/Users/mhrezaei/Documents/Research/negation/negation-and-nlu/env/lib/python3.11/site-packages/huggingface_hub/utils/_validators.py\", line 118, in _inner_fn\n    return fn(*args, **kwargs)\n           ^^^^^^^^^^^^^^^^^^^\n  File \"/Users/mhrezaei/Documents/Research/negation/negation-and-nlu/env/lib/python3.11/site-packages/huggingface_hub/file_download.py\", line 1608, in get_hf_file_metadata\n    hf_raise_for_status(r)\n  File \"/Users/mhrezaei/Documents/Research/negation/negation-and-nlu/env/lib/python3.11/site-packages/huggingface_hub/utils/_errors.py\", line 293, in hf_raise_for_status\n    raise RepositoryNotFoundError(message, response) from e\nhuggingface_hub.utils._errors.RepositoryNotFoundError: 404 Client Error. (Request ID: Root=1-654dc1a5-0f58a9a929f92e36636911f0;bee6c31b-de2c-40c4-9c8a-b7ea09dd7e4e)\n\nRepository Not Found for url: https://huggingface.co/model/resolve/main/config.json.\nPlease make sure you specified the correct `repo_id` and `repo_type`.\nIf you are trying to access a private or gated repo, make sure you are authenticated.\n\nThe above exception was the direct cause of the following exception:\n\nTraceback (most recent call last):\n  File \"/Users/mhrezaei/Documents/Research/negation/negation-and-nlu/env/lib/python3.11/site-packages/jiant/utils/zlog.py\", line 39, in log_context\n    yield self\n  File \"/Users/mhrezaei/Documents/Research/negation/negation-and-nlu/env/lib/python3.11/site-packages/jiant/proj/main/runscript.py\", line 140, in run_loop\n    runner = setup_runner(\n             ^^^^^^^^^^^^^\n  File \"/Users/mhrezaei/Documents/Research/negation/negation-and-nlu/env/lib/python3.11/site-packages/jiant/proj/main/runscript.py\", line 86, in setup_runner\n    jiant_model = jiant_model_setup.setup_jiant_model(\n                  ^^^^^^^^^^^^^^^^^^^^^^^^^^^^^^^^^^^^\n  File \"/Users/mhrezaei/Documents/Research/negation/negation-and-nlu/env/lib/python3.11/site-packages/jiant/proj/main/modeling/model_setup.py\", line 54, in setup_jiant_model\n    hf_model = transformers.AutoModel.from_pretrained(hf_pretrained_model_name_or_path)\n               ^^^^^^^^^^^^^^^^^^^^^^^^^^^^^^^^^^^^^^^^^^^^^^^^^^^^^^^^^^^^^^^^^^^^^^^^\n  File \"/Users/mhrezaei/Documents/Research/negation/negation-and-nlu/env/lib/python3.11/site-packages/transformers/models/auto/auto_factory.py\", line 488, in from_pretrained\n    resolved_config_file = cached_file(\n                           ^^^^^^^^^^^^\n  File \"/Users/mhrezaei/Documents/Research/negation/negation-and-nlu/env/lib/python3.11/site-packages/transformers/utils/hub.py\", line 451, in cached_file\n    raise EnvironmentError(\nOSError: model is not a local folder and is not a valid model identifier listed on 'https://huggingface.co/models'\nIf this is a private repository, make sure to pass a token having permission to this repo either by logging in with `huggingface-cli login` or by passing `token=<your_token>`\n", "TIMESTAMP": 1699594661.907979}
